Traceback (most recent call last):
  File "/opt/anaconda3/envs/jupyter_book_ml/lib/python3.9/site-packages/jupyter_cache/executors/utils.py", line 58, in single_nb_execution
    executenb(
  File "/opt/anaconda3/envs/jupyter_book_ml/lib/python3.9/site-packages/nbclient/client.py", line 1305, in execute
    return NotebookClient(nb=nb, resources=resources, km=km, **kwargs).execute()
  File "/opt/anaconda3/envs/jupyter_book_ml/lib/python3.9/site-packages/jupyter_core/utils/__init__.py", line 165, in wrapped
    return loop.run_until_complete(inner)
  File "/opt/anaconda3/envs/jupyter_book_ml/lib/python3.9/asyncio/base_events.py", line 647, in run_until_complete
    return future.result()
  File "/opt/anaconda3/envs/jupyter_book_ml/lib/python3.9/site-packages/nbclient/client.py", line 705, in async_execute
    await self.async_execute_cell(
  File "/opt/anaconda3/envs/jupyter_book_ml/lib/python3.9/site-packages/nbclient/client.py", line 1058, in async_execute_cell
    await self._check_raise_for_error(cell, cell_index, exec_reply)
  File "/opt/anaconda3/envs/jupyter_book_ml/lib/python3.9/site-packages/nbclient/client.py", line 914, in _check_raise_for_error
    raise CellExecutionError.from_cell_and_msg(cell, exec_reply_content)
nbclient.exceptions.CellExecutionError: An error occurred while executing the following cell:
------------------
import numpy as np # mathematische Operationen
import pandas as pd # Bib fÃ¼r Datenmanipulation
import os # Dateipfade durchgehen (fÃ¼r Daten Laden) 
import seaborn as sns # Bib fÃ¼r Grafiken und Diagramme
import matplotlib.pyplot as plt # Visualisierung von Python Daten

# FÃ¼r das CNN und Datenaufbereitung
import tensorflow as tf 
from tensorflow.keras.preprocessing.image import ImageDataGenerator 
from tensorflow.keras.models import Sequential 
from tensorflow.keras.optimizers import Adam, Adamax 
from tensorflow.keras.layers import BatchNormalization, Dense, Dropout
from sklearn.model_selection import train_test_split 
------------------


[0;31m---------------------------------------------------------------------------[0m
[0;31mModuleNotFoundError[0m                       Traceback (most recent call last)
Cell [0;32mIn[1], line 8[0m
[1;32m      5[0m [38;5;28;01mimport[39;00m [38;5;21;01mmatplotlib[39;00m[38;5;21;01m.[39;00m[38;5;21;01mpyplot[39;00m [38;5;28;01mas[39;00m [38;5;21;01mplt[39;00m [38;5;66;03m# Visualisierung von Python Daten[39;00m
[1;32m      7[0m [38;5;66;03m# FÃ¼r das CNN und Datenaufbereitung[39;00m
[0;32m----> 8[0m [38;5;28;01mimport[39;00m [38;5;21;01mtensorflow[39;00m [38;5;28;01mas[39;00m [38;5;21;01mtf[39;00m 
[1;32m      9[0m [38;5;28;01mfrom[39;00m [38;5;21;01mtensorflow[39;00m[38;5;21;01m.[39;00m[38;5;21;01mkeras[39;00m[38;5;21;01m.[39;00m[38;5;21;01mpreprocessing[39;00m[38;5;21;01m.[39;00m[38;5;21;01mimage[39;00m [38;5;28;01mimport[39;00m ImageDataGenerator 
[1;32m     10[0m [38;5;28;01mfrom[39;00m [38;5;21;01mtensorflow[39;00m[38;5;21;01m.[39;00m[38;5;21;01mkeras[39;00m[38;5;21;01m.[39;00m[38;5;21;01mmodels[39;00m [38;5;28;01mimport[39;00m Sequential 

[0;31mModuleNotFoundError[0m: No module named 'tensorflow'

