Traceback (most recent call last):
  File "/opt/anaconda3/envs/jupyter_book_ml/lib/python3.9/site-packages/jupyter_cache/executors/utils.py", line 58, in single_nb_execution
    executenb(
  File "/opt/anaconda3/envs/jupyter_book_ml/lib/python3.9/site-packages/nbclient/client.py", line 1305, in execute
    return NotebookClient(nb=nb, resources=resources, km=km, **kwargs).execute()
  File "/opt/anaconda3/envs/jupyter_book_ml/lib/python3.9/site-packages/jupyter_core/utils/__init__.py", line 165, in wrapped
    return loop.run_until_complete(inner)
  File "/opt/anaconda3/envs/jupyter_book_ml/lib/python3.9/asyncio/base_events.py", line 647, in run_until_complete
    return future.result()
  File "/opt/anaconda3/envs/jupyter_book_ml/lib/python3.9/site-packages/nbclient/client.py", line 705, in async_execute
    await self.async_execute_cell(
  File "/opt/anaconda3/envs/jupyter_book_ml/lib/python3.9/site-packages/nbclient/client.py", line 1058, in async_execute_cell
    await self._check_raise_for_error(cell, cell_index, exec_reply)
  File "/opt/anaconda3/envs/jupyter_book_ml/lib/python3.9/site-packages/nbclient/client.py", line 914, in _check_raise_for_error
    raise CellExecutionError.from_cell_and_msg(cell, exec_reply_content)
nbclient.exceptions.CellExecutionError: An error occurred while executing the following cell:
------------------
# Load libraries

import os, sys
import wget 
import pandas as pd
import numpy as np
import matplotlib.pyplot as plt
import seaborn as sns
from scipy.io import netcdf
import matplotlib.pyplot as plt
import netCDF4, h5netcdf
import xarray as xr
import glob

from sklearn import tree
from sklearn.ensemble import RandomForestRegressor
from sklearn.metrics import mean_squared_error
from sklearn.metrics import accuracy_score
from sklearn.model_selection import train_test_split
import math
from math import sqrt
from sklearn.tree import DecisionTreeClassifier
from sklearn.tree import DecisionTreeRegressor
from sklearn.metrics import accuracy_score, mean_squared_error, mean_absolute_error, r2_score



import os
os.chdir('..')
os.chdir('C:/Users/karl-/UNI/Neuer_versuch')
print(os.getcwd())

------------------


[0;31m---------------------------------------------------------------------------[0m
[0;31mModuleNotFoundError[0m                       Traceback (most recent call last)
Cell [0;32mIn[1], line 4[0m
[1;32m      1[0m [38;5;66;03m# Load libraries[39;00m
[1;32m      3[0m [38;5;28;01mimport[39;00m [38;5;21;01mos[39;00m[38;5;241m,[39m [38;5;21;01msys[39;00m
[0;32m----> 4[0m [38;5;28;01mimport[39;00m [38;5;21;01mwget[39;00m 
[1;32m      5[0m [38;5;28;01mimport[39;00m [38;5;21;01mpandas[39;00m [38;5;28;01mas[39;00m [38;5;21;01mpd[39;00m
[1;32m      6[0m [38;5;28;01mimport[39;00m [38;5;21;01mnumpy[39;00m [38;5;28;01mas[39;00m [38;5;21;01mnp[39;00m

[0;31mModuleNotFoundError[0m: No module named 'wget'

