Traceback (most recent call last):
  File "/opt/anaconda3/envs/jupyter_book_ml/lib/python3.9/site-packages/jupyter_cache/executors/utils.py", line 58, in single_nb_execution
    executenb(
  File "/opt/anaconda3/envs/jupyter_book_ml/lib/python3.9/site-packages/nbclient/client.py", line 1305, in execute
    return NotebookClient(nb=nb, resources=resources, km=km, **kwargs).execute()
  File "/opt/anaconda3/envs/jupyter_book_ml/lib/python3.9/site-packages/jupyter_core/utils/__init__.py", line 165, in wrapped
    return loop.run_until_complete(inner)
  File "/opt/anaconda3/envs/jupyter_book_ml/lib/python3.9/asyncio/base_events.py", line 647, in run_until_complete
    return future.result()
  File "/opt/anaconda3/envs/jupyter_book_ml/lib/python3.9/site-packages/nbclient/client.py", line 705, in async_execute
    await self.async_execute_cell(
  File "/opt/anaconda3/envs/jupyter_book_ml/lib/python3.9/site-packages/nbclient/client.py", line 1058, in async_execute_cell
    await self._check_raise_for_error(cell, cell_index, exec_reply)
  File "/opt/anaconda3/envs/jupyter_book_ml/lib/python3.9/site-packages/nbclient/client.py", line 914, in _check_raise_for_error
    raise CellExecutionError.from_cell_and_msg(cell, exec_reply_content)
nbclient.exceptions.CellExecutionError: An error occurred while executing the following cell:
------------------
## LIBRARIES

# BASICS
import cv2
import numpy as np
import random
import os, sys
import pandas as pd
import xarray as xr
import rioxarray as rxr
import seaborn as sns
import glob

# RASTERDATEN
import rasterio
from rasterio.mask import mask
from rasterio.windows import from_bounds
from rasterio.plot import show
from PIL import Image

# VEKTORDATEN
import geopandas as gpd
from shapely.geometry import Polygon
from shapely.geometry import box

# KARTEN & PLOTS
import matplotlib.pyplot as plt
import matplotlib.colors as mcolors
from matplotlib_scalebar.scalebar import ScaleBar
from collections import Counter
import plotly.graph_objects as go
import contextily as ctx
from mpl_toolkits.axes_grid1.inset_locator import inset_axes
from mpl_toolkits.mplot3d import Axes3D

# DEEP LEARNING 
from sklearn.preprocessing import LabelEncoder
from sklearn.model_selection import StratifiedShuffleSplit
from sklearn.neural_network import MLPClassifier 
from sklearn.metrics import confusion_matrix, accuracy_score, classification_report
from sklearn.model_selection import train_test_split

------------------


[0;31m---------------------------------------------------------------------------[0m
[0;31mModuleNotFoundError[0m                       Traceback (most recent call last)
Cell [0;32mIn[4], line 4[0m
[1;32m      1[0m [38;5;66;03m## LIBRARIES[39;00m
[1;32m      2[0m 
[1;32m      3[0m [38;5;66;03m# BASICS[39;00m
[0;32m----> 4[0m [38;5;28;01mimport[39;00m [38;5;21;01mcv2[39;00m
[1;32m      5[0m [38;5;28;01mimport[39;00m [38;5;21;01mnumpy[39;00m [38;5;28;01mas[39;00m [38;5;21;01mnp[39;00m
[1;32m      6[0m [38;5;28;01mimport[39;00m [38;5;21;01mrandom[39;00m

[0;31mModuleNotFoundError[0m: No module named 'cv2'

